Starting test with workers=256
Launched task.. waiting
Result : uname_result(system='Linux', node='exp-6-20', release='4.18.0-477.15.1.el8_8.x86_64', version='#1 SMP Wed Jun 28 15:04:18 UTC 2023', machine='x86_64')
Traceback (most recent call last):
  File "/home/vhayot/flox_experiments/test.py", line 125, in <module>
    test_sequence(num_workers=int(args.nodes) * int(args.workers_per_node),
  File "/home/vhayot/flox_experiments/test.py", line 65, in test_sequence
    [future.result() for future in futures]
  File "/home/vhayot/flox_experiments/test.py", line 65, in <listcomp>
    [future.result() for future in futures]
     ^^^^^^^^^^^^^^^
  File "/home/vhayot/spack/var/spack/environments/mochi/.spack-env/._view/mqqgoppvczvz5n73nj3tj3aecze2kzdo/lib/python3.11/concurrent/futures/_base.py", line 449, in result
    return self.__get_result()
           ^^^^^^^^^^^^^^^^^^^
  File "/home/vhayot/spack/var/spack/environments/mochi/.spack-env/._view/mqqgoppvczvz5n73nj3tj3aecze2kzdo/lib/python3.11/concurrent/futures/_base.py", line 401, in __get_result
    raise self._exception
  File "/home/vhayot/spack/var/spack/environments/mochi/.spack-env/view/lib/python3.11/site-packages/parsl/dataflow/dflow.py", line 302, in handle_exec_update
    res = self._unwrap_remote_exception_wrapper(future)
          ^^^^^^^^^^^^^^^^^^^^^^^^^^^^^^^^^^^^^^^^^^^^^
  File "/home/vhayot/spack/var/spack/environments/mochi/.spack-env/view/lib/python3.11/site-packages/parsl/dataflow/dflow.py", line 572, in _unwrap_remote_exception_wrapper
    result.reraise()
  File "/home/vhayot/spack/var/spack/environments/mochi/.spack-env/view/lib/python3.11/site-packages/parsl/app/errors.py", line 118, in reraise
    raise v
  File "/home/vhayot/spack/var/spack/environments/mochi/.spack-env/view/lib/python3.11/site-packages/parsl/app/errors.py", line 141, in wrapper
    return func(*args, **kwargs)
^^^^^^^^^^^^^^^
  File "/home/vhayot/flox_experiments/test.py", line 38, in sleeper
    store = Store.from_config(config)
      ^^^^^^^^^^^^^^^^^
  File "/home/vhayot/spack/var/spack/environments/mochi/.spack-env/view/lib/python3.11/site-packages/proxystore/store/base.py", line 207, in from_config
    config = config.copy()  # Avoid messing with callers version
  ^^^^^^^^^^^^^^^^^
AttributeError: 'NoneType' object has no attribute 'copy'
Starting test with workers=256
Launched task.. waiting
Result : uname_result(system='Linux', node='exp-5-21', release='4.18.0-477.15.1.el8_8.x86_64', version='#1 SMP Wed Jun 28 15:04:18 UTC 2023', machine='x86_64')
[num_workers=256][task_count=512][sleep_dur=0][input_data=0][output_data=0]Launched tasks in 0.226s
[num_workers=256][task_count=512][sleep_dur=0][input_data=0][output_data=0]Finished noop tasks in 0.812s
[num_workers=256][task_count=512][sleep_dur=0][input_data=0][output_data=0]Throughput  630.898 Tasks/s
[num_workers=256][task_count=512][sleep_dur=1][input_data=0][output_data=0]Launched tasks in 0.172s
[num_workers=256][task_count=512][sleep_dur=1][input_data=0][output_data=0]Finished noop tasks in 5.045s
[num_workers=256][task_count=512][sleep_dur=1][input_data=0][output_data=0]Throughput  101.479 Tasks/s
[num_workers=256][task_count=512][sleep_dur=0][input_data=4][output_data=4]Launched tasks in 10.214s
[num_workers=256][task_count=512][sleep_dur=0][input_data=4][output_data=4]Finished noop tasks in 10.242s
[num_workers=256][task_count=512][sleep_dur=0][input_data=4][output_data=4]Throughput  49.991 Tasks/s
[num_workers=256][task_count=512][sleep_dur=1][input_data=4][output_data=4]Launched tasks in 10.058s
[num_workers=256][task_count=512][sleep_dur=1][input_data=4][output_data=4]Finished noop tasks in 11.105s
[num_workers=256][task_count=512][sleep_dur=1][input_data=4][output_data=4]Throughput  46.104 Tasks/s
Traceback (most recent call last):
  File "/home/vhayot/flox_experiments/test.py", line 128, in <module>
    test_sequence(num_workers=int(args.nodes) * int(args.workers_per_node),
  File "/home/vhayot/flox_experiments/test.py", line 68, in test_sequence
    [future.result() for future in futures]
  File "/home/vhayot/flox_experiments/test.py", line 68, in <listcomp>
    [future.result() for future in futures]
     ^^^^^^^^^^^^^^^
  File "/home/vhayot/spack/var/spack/environments/mochi/.spack-env/._view/mqqgoppvczvz5n73nj3tj3aecze2kzdo/lib/python3.11/concurrent/futures/_base.py", line 449, in result
    return self.__get_result()
           ^^^^^^^^^^^^^^^^^^^
  File "/home/vhayot/spack/var/spack/environments/mochi/.spack-env/._view/mqqgoppvczvz5n73nj3tj3aecze2kzdo/lib/python3.11/concurrent/futures/_base.py", line 401, in __get_result
    raise self._exception
  File "/home/vhayot/spack/var/spack/environments/mochi/.spack-env/view/lib/python3.11/site-packages/parsl/dataflow/dflow.py", line 302, in handle_exec_update
    res = self._unwrap_remote_exception_wrapper(future)
          ^^^^^^^^^^^^^^^^^^^^^^^^^^^^^^^^^^^^^^^^^^^^^
  File "/home/vhayot/spack/var/spack/environments/mochi/.spack-env/view/lib/python3.11/site-packages/parsl/dataflow/dflow.py", line 570, in _unwrap_remote_exception_wrapper
    result = future.result()
             ^^^^^^^^^^^^^^^
  File "/home/vhayot/spack/var/spack/environments/mochi/.spack-env/._view/mqqgoppvczvz5n73nj3tj3aecze2kzdo/lib/python3.11/concurrent/futures/_base.py", line 449, in result
    return self.__get_result()
           ^^^^^^^^^^^^^^^^^^^
  File "/home/vhayot/spack/var/spack/environments/mochi/.spack-env/._view/mqqgoppvczvz5n73nj3tj3aecze2kzdo/lib/python3.11/concurrent/futures/_base.py", line 401, in __get_result
    raise self._exception
  File "/home/vhayot/spack/var/spack/environments/mochi/.spack-env/view/lib/python3.11/site-packages/parsl/dataflow/dflow.py", line 627, in launch_if_ready
    exec_fu = self.launch_task(task_record)
              ^^^^^^^^^^^^^^^^^^^^^^^^^^^^^
  File "/home/vhayot/spack/var/spack/environments/mochi/.spack-env/view/lib/python3.11/site-packages/parsl/dataflow/dflow.py", line 719, in launch_task
    exec_fu = executor.submit(executable, task_record['resource_specification'], *args, **kwargs)
              ^^^^^^^^^^^^^^^^^^^^^^^^^^^^^^^^^^^^^^^^^^^^^^^^^^^^^^^^^^^^^^^^^^^^^^^^^^^^^^^^^^^
  File "/home/vhayot/spack/var/spack/environments/mochi/.spack-env/view/lib/python3.11/site-packages/parsl/executors/high_throughput/executor.py", line 645, in submit
    self.outgoing_q.put(msg)
  File "/home/vhayot/spack/var/spack/environments/mochi/.spack-env/view/lib/python3.11/site-packages/parsl/executors/high_throughput/zmq_pipes.py", line 125, in put
    self.zmq_socket.send_pyobj(message, copy=True)
  File "/home/vhayot/spack/var/spack/environments/mochi/.spack-env/view/lib/python3.11/site-packages/zmq/sugar/socket.py", line 955, in send_pyobj
    return self.send(msg, flags=flags, **kwargs)
           ^^^^^^^^^^^^^^^^^^^^^^^^^^^^^^^^^^^^^
  File "/home/vhayot/spack/var/spack/environments/mochi/.spack-env/view/lib/python3.11/site-packages/zmq/sugar/socket.py", line 696, in send
    return super().send(data, flags=flags, copy=copy, track=track)
           ^^^^^^^^^^^^^^^^^^^^^^^^^^^^^^^^^^^^^^^^^^^^^^^^^^^^^^^
  File "zmq/backend/cython/socket.pyx", line 742, in zmq.backend.cython.socket.Socket.send
  File "zmq/backend/cython/socket.pyx", line 789, in zmq.backend.cython.socket.Socket.send
  File "zmq/backend/cython/socket.pyx", line 243, in zmq.backend.cython.socket._send_copy
  File "zmq/backend/cython/checkrc.pxd", line 28, in zmq.backend.cython.checkrc._check_rc
zmq.error.ZMQError: Cannot allocate memory
