Starting test with workers=32
Launched task.. waiting
Result : uname_result(system='Linux', node='exp-10-35', release='4.18.0-477.15.1.el8_8.x86_64', version='#1 SMP Wed Jun 28 15:04:18 UTC 2023', machine='x86_64')
Traceback (most recent call last):
  File "/home/vhayot/spack/var/spack/environments/mochi/.spack-env/view/lib/python3.11/site-packages/lazy_object_proxy/slots.py", line 97, in __wrapped__
    return __getattr__(self, '__target__')
           ^^^^^^^^^^^^^^^^^^^^^^^^^^^^^^^
AttributeError: 'Proxy' object has no attribute '__target__'

During handling of the above exception, another exception occurred:

Traceback (most recent call last):
  File "/home/vhayot/flox_experiments/test.py", line 131, in <module>
    test_sequence(num_workers=int(args.nodes) * int(args.workers_per_node),
  File "/home/vhayot/flox_experiments/test.py", line 71, in test_sequence
    [future.result() for future in futures]
  File "/home/vhayot/flox_experiments/test.py", line 71, in <listcomp>
    [future.result() for future in futures]
     ^^^^^^^^^^^^^^^
  File "/home/vhayot/spack/var/spack/environments/mochi/.spack-env/._view/mqqgoppvczvz5n73nj3tj3aecze2kzdo/lib/python3.11/concurrent/futures/_base.py", line 456, in result
    return self.__get_result()
           ^^^^^^^^^^^^^^^^^^^
  File "/home/vhayot/spack/var/spack/environments/mochi/.spack-env/._view/mqqgoppvczvz5n73nj3tj3aecze2kzdo/lib/python3.11/concurrent/futures/_base.py", line 401, in __get_result
    raise self._exception
  File "/home/vhayot/spack/var/spack/environments/mochi/.spack-env/view/lib/python3.11/site-packages/parsl/dataflow/dflow.py", line 302, in handle_exec_update
    res = self._unwrap_remote_exception_wrapper(future)
          ^^^^^^^^^^^^^^^^^^^^^^^^^^^^^^^^^^^^^^^^^^^^^
  File "/home/vhayot/spack/var/spack/environments/mochi/.spack-env/view/lib/python3.11/site-packages/parsl/dataflow/dflow.py", line 571, in _unwrap_remote_exception_wrapper
    if isinstance(result, RemoteExceptionWrapper):
       ^^^^^^^^^^^^^^^^^^^^^^^^^^^^^^^^^^^^^^^^^^
  File "/home/vhayot/spack/var/spack/environments/mochi/.spack-env/view/lib/python3.11/site-packages/lazy_object_proxy/slots.py", line 125, in __class__
    return self.__wrapped__.__class__
           ^^^^^^^^^^^^^^^^
  File "/home/vhayot/spack/var/spack/environments/mochi/.spack-env/view/lib/python3.11/site-packages/lazy_object_proxy/slots.py", line 103, in __wrapped__
    target = factory()
             ^^^^^^^^^
  File "/home/vhayot/spack/var/spack/environments/mochi/.spack-env/view/lib/python3.11/site-packages/proxystore/store/factory.py", line 79, in __call__
    obj = self.resolve()
          ^^^^^^^^^^^^^^
  File "/home/vhayot/spack/var/spack/environments/mochi/.spack-env/view/lib/python3.11/site-packages/proxystore/store/factory.py", line 119, in resolve
    obj = store.get(
          ^^^^^^^^^^
  File "/home/vhayot/spack/var/spack/environments/mochi/.spack-env/view/lib/python3.11/site-packages/proxystore/store/base.py", line 399, in get
    value = self.connector.get(key)
            ^^^^^^^^^^^^^^^^^^^^^^^
  File "/home/vhayot/spack/var/spack/environments/mochi/.spack-env/view/lib/python3.11/site-packages/proxystore_ex/connectors/dim/margo.py", line 305, in get
    (result,) = self._send_rpcs([rpc])
                ^^^^^^^^^^^^^^^^^^^^^^
  File "/home/vhayot/spack/var/spack/environments/mochi/.spack-env/view/lib/python3.11/site-packages/proxystore_ex/connectors/dim/margo.py", line 203, in _send_rpcs
    result = self._rpcs[rpc.operation].on(server_url)(
             ^^^^^^^^^^^^^^^^^^^^^^^^^^^^^^^^^^^^^^^^^
  File "/home/vhayot/spack/var/spack/environments/mochi/.spack-env/view/lib/python3.11/site-packages/pymargo/core.py", line 204, in __call__
    return self._forward(*args, timeout=timeout, **kwargs)
           ^^^^^^^^^^^^^^^^^^^^^^^^^^^^^^^^^^^^^^^^^^^^^^^
  File "/home/vhayot/spack/var/spack/environments/mochi/.spack-env/view/lib/python3.11/site-packages/pymargo/core.py", line 182, in _forward
    raw_response = self.handle._forward(provider_id=self.provider_id,
                   ^^^^^^^^^^^^^^^^^^^^^^^^^^^^^^^^^^^^^^^^^^^^^^^^^^
_pymargo.MargoException: margo_provider_forward_timed() returned 20
Starting test with workers=32
Launched task.. waiting
Result : uname_result(system='Linux', node='exp-4-18', release='4.18.0-477.15.1.el8_8.x86_64', version='#1 SMP Wed Jun 28 15:04:18 UTC 2023', machine='x86_64')
Traceback (most recent call last):
  File "/home/vhayot/spack/var/spack/environments/mochi/.spack-env/view/lib/python3.11/site-packages/lazy_object_proxy/slots.py", line 97, in __wrapped__
    return __getattr__(self, '__target__')
           ^^^^^^^^^^^^^^^^^^^^^^^^^^^^^^^
AttributeError: 'Proxy' object has no attribute '__target__'

During handling of the above exception, another exception occurred:

Traceback (most recent call last):
  File "/home/vhayot/flox_experiments/test.py", line 133, in <module>
    test_sequence(num_workers=int(args.nodes) * int(args.workers_per_node),
  File "/home/vhayot/flox_experiments/test.py", line 73, in test_sequence
    [future.result() for future in futures]
  File "/home/vhayot/flox_experiments/test.py", line 73, in <listcomp>
    [future.result() for future in futures]
     ^^^^^^^^^^^^^^^
  File "/home/vhayot/spack/var/spack/environments/mochi/.spack-env/._view/mqqgoppvczvz5n73nj3tj3aecze2kzdo/lib/python3.11/concurrent/futures/_base.py", line 456, in result
    return self.__get_result()
           ^^^^^^^^^^^^^^^^^^^
  File "/home/vhayot/spack/var/spack/environments/mochi/.spack-env/._view/mqqgoppvczvz5n73nj3tj3aecze2kzdo/lib/python3.11/concurrent/futures/_base.py", line 401, in __get_result
    raise self._exception
  File "/home/vhayot/spack/var/spack/environments/mochi/.spack-env/view/lib/python3.11/site-packages/parsl/dataflow/dflow.py", line 302, in handle_exec_update
    res = self._unwrap_remote_exception_wrapper(future)
          ^^^^^^^^^^^^^^^^^^^^^^^^^^^^^^^^^^^^^^^^^^^^^
  File "/home/vhayot/spack/var/spack/environments/mochi/.spack-env/view/lib/python3.11/site-packages/parsl/dataflow/dflow.py", line 571, in _unwrap_remote_exception_wrapper
    if isinstance(result, RemoteExceptionWrapper):
       ^^^^^^^^^^^^^^^^^^^^^^^^^^^^^^^^^^^^^^^^^^
  File "/home/vhayot/spack/var/spack/environments/mochi/.spack-env/view/lib/python3.11/site-packages/lazy_object_proxy/slots.py", line 125, in __class__
    return self.__wrapped__.__class__
           ^^^^^^^^^^^^^^^^
  File "/home/vhayot/spack/var/spack/environments/mochi/.spack-env/view/lib/python3.11/site-packages/lazy_object_proxy/slots.py", line 103, in __wrapped__
    target = factory()
             ^^^^^^^^^
  File "/home/vhayot/spack/var/spack/environments/mochi/.spack-env/view/lib/python3.11/site-packages/proxystore/store/factory.py", line 79, in __call__
    obj = self.resolve()
          ^^^^^^^^^^^^^^
  File "/home/vhayot/spack/var/spack/environments/mochi/.spack-env/view/lib/python3.11/site-packages/proxystore/store/factory.py", line 119, in resolve
    obj = store.get(
          ^^^^^^^^^^
  File "/home/vhayot/spack/var/spack/environments/mochi/.spack-env/view/lib/python3.11/site-packages/proxystore/store/base.py", line 399, in get
    value = self.connector.get(key)
            ^^^^^^^^^^^^^^^^^^^^^^^
  File "/home/vhayot/spack/var/spack/environments/mochi/.spack-env/view/lib/python3.11/site-packages/proxystore_ex/connectors/dim/margo.py", line 305, in get
    (result,) = self._send_rpcs([rpc])
                ^^^^^^^^^^^^^^^^^^^^^^
  File "/home/vhayot/spack/var/spack/environments/mochi/.spack-env/view/lib/python3.11/site-packages/proxystore_ex/connectors/dim/margo.py", line 203, in _send_rpcs
    result = self._rpcs[rpc.operation].on(server_url)(
             ^^^^^^^^^^^^^^^^^^^^^^^^^^^^^^^^^^^^^^^^^
  File "/home/vhayot/spack/var/spack/environments/mochi/.spack-env/view/lib/python3.11/site-packages/pymargo/core.py", line 204, in __call__
    return self._forward(*args, timeout=timeout, **kwargs)
           ^^^^^^^^^^^^^^^^^^^^^^^^^^^^^^^^^^^^^^^^^^^^^^^
  File "/home/vhayot/spack/var/spack/environments/mochi/.spack-env/view/lib/python3.11/site-packages/pymargo/core.py", line 182, in _forward
    raw_response = self.handle._forward(provider_id=self.provider_id,
                   ^^^^^^^^^^^^^^^^^^^^^^^^^^^^^^^^^^^^^^^^^^^^^^^^^^
_pymargo.MargoException: margo_provider_forward_timed() returned 20
Starting test with workers=32
Launched task.. waiting
Result : uname_result(system='Linux', node='exp-3-26', release='4.18.0-477.15.1.el8_8.x86_64', version='#1 SMP Wed Jun 28 15:04:18 UTC 2023', machine='x86_64')
Traceback (most recent call last):
  File "/home/vhayot/flox_experiments/test.py", line 133, in <module>
    test_sequence(num_workers=int(args.nodes) * int(args.workers_per_node),
  File "/home/vhayot/flox_experiments/test.py", line 73, in test_sequence
    [future.result() for future in futures]
  File "/home/vhayot/flox_experiments/test.py", line 73, in <listcomp>
    [future.result() for future in futures]
     ^^^^^^^^^^^^^^^
  File "/home/vhayot/spack/var/spack/environments/mochi/.spack-env/._view/mqqgoppvczvz5n73nj3tj3aecze2kzdo/lib/python3.11/concurrent/futures/_base.py", line 456, in result
    return self.__get_result()
           ^^^^^^^^^^^^^^^^^^^
  File "/home/vhayot/spack/var/spack/environments/mochi/.spack-env/._view/mqqgoppvczvz5n73nj3tj3aecze2kzdo/lib/python3.11/concurrent/futures/_base.py", line 401, in __get_result
    raise self._exception
  File "/home/vhayot/spack/var/spack/environments/mochi/.spack-env/view/lib/python3.11/site-packages/parsl/dataflow/dflow.py", line 302, in handle_exec_update
    res = self._unwrap_remote_exception_wrapper(future)
          ^^^^^^^^^^^^^^^^^^^^^^^^^^^^^^^^^^^^^^^^^^^^^
  File "/home/vhayot/spack/var/spack/environments/mochi/.spack-env/view/lib/python3.11/site-packages/parsl/dataflow/dflow.py", line 570, in _unwrap_remote_exception_wrapper
    result = future.result()
             ^^^^^^^^^^^^^^^
  File "/home/vhayot/spack/var/spack/environments/mochi/.spack-env/._view/mqqgoppvczvz5n73nj3tj3aecze2kzdo/lib/python3.11/concurrent/futures/_base.py", line 449, in result
    return self.__get_result()
           ^^^^^^^^^^^^^^^^^^^
  File "/home/vhayot/spack/var/spack/environments/mochi/.spack-env/._view/mqqgoppvczvz5n73nj3tj3aecze2kzdo/lib/python3.11/concurrent/futures/_base.py", line 401, in __get_result
    raise self._exception
  File "/home/vhayot/spack/var/spack/environments/mochi/.spack-env/view/lib/python3.11/site-packages/parsl/executors/high_throughput/executor.py", line 480, in _queue_management_worker
    s.reraise()
  File "/home/vhayot/spack/var/spack/environments/mochi/.spack-env/view/lib/python3.11/site-packages/parsl/app/errors.py", line 118, in reraise
    raise v
  File "/home/vhayot/spack/var/spack/environments/mochi/.spack-env/view/lib/python3.11/site-packages/parsl/executors/high_throughput/interchange.py", line 586, in expire_bad_managers
    raise ManagerLost(manager_id, m['hostname'])
^^^^^^^
parsl.executors.high_throughput.interchange.ManagerLost: Task failure due to loss of manager ffb53bf0087f on host exp-3-26
Starting test with workers=32
Launched task.. waiting
Result : uname_result(system='Linux', node='exp-9-10', release='4.18.0-477.15.1.el8_8.x86_64', version='#1 SMP Wed Jun 28 15:04:18 UTC 2023', machine='x86_64')
Traceback (most recent call last):
  File "/home/vhayot/flox_experiments/test.py", line 133, in <module>
    test_sequence(num_workers=int(args.nodes) * int(args.workers_per_node),
  File "/home/vhayot/flox_experiments/test.py", line 73, in test_sequence
    [future.result() for future in futures]
  File "/home/vhayot/flox_experiments/test.py", line 73, in <listcomp>
    [future.result() for future in futures]
     ^^^^^^^^^^^^^^^
  File "/home/vhayot/spack/var/spack/environments/mochi/.spack-env/._view/mqqgoppvczvz5n73nj3tj3aecze2kzdo/lib/python3.11/concurrent/futures/_base.py", line 456, in result
    return self.__get_result()
           ^^^^^^^^^^^^^^^^^^^
  File "/home/vhayot/spack/var/spack/environments/mochi/.spack-env/._view/mqqgoppvczvz5n73nj3tj3aecze2kzdo/lib/python3.11/concurrent/futures/_base.py", line 401, in __get_result
    raise self._exception
  File "/home/vhayot/spack/var/spack/environments/mochi/.spack-env/view/lib/python3.11/site-packages/parsl/dataflow/dflow.py", line 302, in handle_exec_update
    res = self._unwrap_remote_exception_wrapper(future)
          ^^^^^^^^^^^^^^^^^^^^^^^^^^^^^^^^^^^^^^^^^^^^^
  File "/home/vhayot/spack/var/spack/environments/mochi/.spack-env/view/lib/python3.11/site-packages/parsl/dataflow/dflow.py", line 572, in _unwrap_remote_exception_wrapper
    result.reraise()
  File "/home/vhayot/spack/var/spack/environments/mochi/.spack-env/view/lib/python3.11/site-packages/parsl/app/errors.py", line 118, in reraise
    raise v
  File "/home/vhayot/spack/var/spack/environments/mochi/.spack-env/view/lib/python3.11/site-packages/parsl/app/errors.py", line 141, in wrapper
    return func(*args, **kwargs)
^^^^^^^^^^^^^^^
  File "/home/vhayot/flox_experiments/test.py", line 46, in sleeper
    output_string = store.proxy(output_string)
  ^^^^^^^^^^^^^^^^^
  File "/home/vhayot/spack/var/spack/environments/mochi/.spack-env/view/lib/python3.11/site-packages/proxystore/store/base.py", line 525, in proxy
    key = self.put(obj, serializer=serializer, **kwargs)
^^^^^^^^^^^^^^^
  File "/home/vhayot/spack/var/spack/environments/mochi/.spack-env/view/lib/python3.11/site-packages/proxystore/store/base.py", line 794, in put
    key = self.connector.put(obj, **kwargs)
^^^^^^^^^^^^^^^
  File "/home/vhayot/spack/var/spack/environments/mochi/.spack-env/view/lib/python3.11/site-packages/proxystore_ex/connectors/dim/margo.py", line 357, in put
    self._send_rpcs([rpc])
  ^^^^^^^^^^^^^^^^^
  File "/home/vhayot/spack/var/spack/environments/mochi/.spack-env/view/lib/python3.11/site-packages/proxystore_ex/connectors/dim/margo.py", line 203, in _send_rpcs
    result = self._rpcs[rpc.operation].on(server_url)(
^^^^^^^^^^^^^^^
  File "/home/vhayot/spack/var/spack/environments/mochi/.spack-env/view/lib/python3.11/site-packages/pymargo/core.py", line 204, in __call__
    return self._forward(*args, timeout=timeout, **kwargs)
^^^^^^^^^^^^^^^
  File "/home/vhayot/spack/var/spack/environments/mochi/.spack-env/view/lib/python3.11/site-packages/pymargo/core.py", line 182, in _forward
    raw_response = self.handle._forward(provider_id=self.provider_id,
  ^^^^^^^^^^^^^^^^^
_pymargo.MargoException: margo_provider_forward_timed() returned 20
